<?xml version="1.0"?>

<root xmlns:xi="http://www.w3.org/2001/XInclude"
	xmlns:gazebo="http://playerstage.sourceforge.net/gazebo/xmlschema/#gz"
    xmlns:model="http://playerstage.sourceforge.net/gazebo/xmlschema/#model"
	xmlns:sensor="http://playerstage.sourceforge.net/gazebo/xmlschema/#sensor"
	xmlns:body="http://playerstage.sourceforge.net/gazebo/xmlschema/#body"
    xmlns:geom="http://playerstage.sourceforge.net/gazebo/xmlschema/#geom"
    xmlns:joint="http://playerstage.sourceforge.net/gazebo/xmlschema/#joint"
	xmlns:controller="http://playerstage.sourceforge.net/gazebo/xmlschema/#controller"
	xmlns:interface="http://playerstage.sourceforge.net/gazebo/xmlschema/#interface"
	xmlns:rendering="http://playerstage.sourceforge.net/gazebo/xmlschema/#rendering"
    xmlns:renderable="http://playerstage.sourceforge.net/gazebo/xmlschema/#renderable"
    xmlns:physics="http://playerstage.sourceforge.net/gazebo/xmlschema/#physics"
	xmlns:xacro="http://ros.org/wiki/xacro">

    <xacro:include filename="$(find kinova_description)/urdf/parts/common.urdf.xacro" />

    <!-- Shoulder link with revolute joint at the output -->
    <!-- Suggested parameters: jaco2 link_1 link_2 joint_2 --> 

    <xacro:macro name="jaco2_shoulder" params="prefix name child_link joint">
        <!-- Base link model -->
        <link name="${prefix}_${name}">
            <inertial>
                <origin xyz="0.0692 0.0001 -0.0103" rpy="0 0 0"/>
                <mass value="0.748"/>
                <inertia ixx="1.02e-2"
                         ixy="-5.21e-7"
                         ixz="-2.12e-3"
                         iyy="3.25e-2"
                         iyz="-4.14e-7"
                         izz="3.54e-2"/>
            </inertial>
            <visual>
                <geometry>
                    <mesh
                        filename="package://kinova_description/meshes/jaco2_link_1.dae"/>
                </geometry>
                <material name="carbon_fiber">
                    <color rgba="0.792156862745098 0.819607843137255 0.933333333333333 1" />
                </material>
            </visual>
            <collision>
                <geometry>
                    <mesh
                        filename="package://kinova_description/meshes/jaco2_link_1.dae"/>
                </geometry>
            </collision>
        </link>

        <!-- Second rotation (shoulder pitch) -->
        <joint name="${prefix}_${joint}" type="revolute">
            <parent link="${prefix}_${name}"/>
            <child link="${prefix}_${child_link}"/>
            <origin xyz="0 0 -0.1185" rpy="-${J_PI/2} ${J_PI} 0"/>
            <axis xyz="0 0 1"/>
            <limit effort="30" velocity="0.35" lower="${-J_PI}" upper="${0}"/>
         </joint>
         <transmission name="${prefix}_${joint}_trans">
            <type>transmission_interface/SimpleTransmission</type>
            <joint name="${prefix}_${joint}">
                <hardwareInterface>EffortJointInterface</hardwareInterface>
            </joint>
            <actuator name="${prefix}_${joint}_motor">
                <mechanicalReduction>1.0</mechanicalReduction>
            </actuator>
        </transmission>

    </xacro:macro>

</root>

